[2024-09-15 16:45:18,945] {taskinstance.py:1179} INFO - Dependencies all met for <TaskInstance: dag_clima.cargar_data manual__2024-09-15T16:45:13.422905+00:00 [queued]>
[2024-09-15 16:45:18,956] {taskinstance.py:1179} INFO - Dependencies all met for <TaskInstance: dag_clima.cargar_data manual__2024-09-15T16:45:13.422905+00:00 [queued]>
[2024-09-15 16:45:18,957] {taskinstance.py:1376} INFO - 
--------------------------------------------------------------------------------
[2024-09-15 16:45:18,958] {taskinstance.py:1377} INFO - Starting attempt 1 of 2
[2024-09-15 16:45:18,959] {taskinstance.py:1378} INFO - 
--------------------------------------------------------------------------------
[2024-09-15 16:45:18,977] {taskinstance.py:1397} INFO - Executing <Task(PythonOperator): cargar_data> on 2024-09-15 16:45:13.422905+00:00
[2024-09-15 16:45:18,982] {standard_task_runner.py:52} INFO - Started process 659 to run task
[2024-09-15 16:45:18,985] {standard_task_runner.py:79} INFO - Running: ['***', 'tasks', 'run', 'dag_clima', 'cargar_data', 'manual__2024-09-15T16:45:13.422905+00:00', '--job-id', '19', '--raw', '--subdir', 'DAGS_FOLDER/dag_clima.py', '--cfg-path', '/tmp/tmpxsp1355g', '--error-file', '/tmp/tmplakhynam']
[2024-09-15 16:45:18,987] {standard_task_runner.py:80} INFO - Job 19: Subtask cargar_data
[2024-09-15 16:45:19,084] {task_command.py:371} INFO - Running <TaskInstance: dag_clima.cargar_data manual__2024-09-15T16:45:13.422905+00:00 [running]> on host 4abe27884306
[2024-09-15 16:45:19,184] {taskinstance.py:1591} INFO - Exporting the following env vars:
AIRFLOW_CTX_DAG_OWNER=EmanuelGomez
AIRFLOW_CTX_DAG_ID=dag_clima
AIRFLOW_CTX_TASK_ID=cargar_data
AIRFLOW_CTX_EXECUTION_DATE=2024-09-15T16:45:13.422905+00:00
AIRFLOW_CTX_TRY_NUMBER=1
AIRFLOW_CTX_DAG_RUN_ID=manual__2024-09-15T16:45:13.422905+00:00
[2024-09-15 16:45:20,512] {logging_mixin.py:115} INFO - Conexi√≥n exitosa a Redshift
[2024-09-15 16:45:20,527] {taskinstance.py:1909} ERROR - Task failed with exception
Traceback (most recent call last):
  File "/home/airflow/.local/lib/python3.7/site-packages/airflow/operators/python.py", line 171, in execute
    return_value = self.execute_callable()
  File "/home/airflow/.local/lib/python3.7/site-packages/airflow/operators/python.py", line 189, in execute_callable
    return self.python_callable(*self.op_args, **self.op_kwargs)
  File "/opt/airflow/dags/src/cargar_data.py", line 33, in cargar_data
    df = pd.DataFrame(xcom_value)
  File "/home/airflow/.local/lib/python3.7/site-packages/pandas/core/frame.py", line 730, in __init__
    raise ValueError("DataFrame constructor not properly called!")
ValueError: DataFrame constructor not properly called!
[2024-09-15 16:45:20,551] {taskinstance.py:1420} INFO - Marking task as UP_FOR_RETRY. dag_id=dag_clima, task_id=cargar_data, execution_date=20240915T164513, start_date=20240915T164518, end_date=20240915T164520
[2024-09-15 16:45:20,570] {standard_task_runner.py:97} ERROR - Failed to execute job 19 for task cargar_data (DataFrame constructor not properly called!; 659)
[2024-09-15 16:45:20,609] {local_task_job.py:156} INFO - Task exited with return code 1
[2024-09-15 16:45:20,645] {local_task_job.py:273} INFO - 0 downstream tasks scheduled from follow-on schedule check
