[2024-09-15 17:03:11,270] {taskinstance.py:1179} INFO - Dependencies all met for <TaskInstance: dag_clima.cargar_data manual__2024-09-15T17:03:06.109087+00:00 [queued]>
[2024-09-15 17:03:11,283] {taskinstance.py:1179} INFO - Dependencies all met for <TaskInstance: dag_clima.cargar_data manual__2024-09-15T17:03:06.109087+00:00 [queued]>
[2024-09-15 17:03:11,284] {taskinstance.py:1376} INFO - 
--------------------------------------------------------------------------------
[2024-09-15 17:03:11,285] {taskinstance.py:1377} INFO - Starting attempt 1 of 1
[2024-09-15 17:03:11,286] {taskinstance.py:1378} INFO - 
--------------------------------------------------------------------------------
[2024-09-15 17:03:11,305] {taskinstance.py:1397} INFO - Executing <Task(PythonOperator): cargar_data> on 2024-09-15 17:03:06.109087+00:00
[2024-09-15 17:03:11,312] {standard_task_runner.py:52} INFO - Started process 1327 to run task
[2024-09-15 17:03:11,315] {standard_task_runner.py:79} INFO - Running: ['***', 'tasks', 'run', 'dag_clima', 'cargar_data', 'manual__2024-09-15T17:03:06.109087+00:00', '--job-id', '37', '--raw', '--subdir', 'DAGS_FOLDER/dag_clima.py', '--cfg-path', '/tmp/tmplmw5uwsh', '--error-file', '/tmp/tmpmq6yjemw']
[2024-09-15 17:03:11,317] {standard_task_runner.py:80} INFO - Job 37: Subtask cargar_data
[2024-09-15 17:03:11,403] {task_command.py:371} INFO - Running <TaskInstance: dag_clima.cargar_data manual__2024-09-15T17:03:06.109087+00:00 [running]> on host 4abe27884306
[2024-09-15 17:03:11,498] {taskinstance.py:1591} INFO - Exporting the following env vars:
AIRFLOW_CTX_DAG_OWNER=EmanuelGomez
AIRFLOW_CTX_DAG_ID=dag_clima
AIRFLOW_CTX_TASK_ID=cargar_data
AIRFLOW_CTX_EXECUTION_DATE=2024-09-15T17:03:06.109087+00:00
AIRFLOW_CTX_TRY_NUMBER=1
AIRFLOW_CTX_DAG_RUN_ID=manual__2024-09-15T17:03:06.109087+00:00
[2024-09-15 17:03:12,941] {logging_mixin.py:115} INFO - Conexi√≥n exitosa a Redshift
[2024-09-15 17:03:12,958] {logging_mixin.py:115} INFO - <class 'str'>
[2024-09-15 17:03:12,959] {taskinstance.py:1909} ERROR - Task failed with exception
Traceback (most recent call last):
  File "/home/airflow/.local/lib/python3.7/site-packages/airflow/operators/python.py", line 171, in execute
    return_value = self.execute_callable()
  File "/home/airflow/.local/lib/python3.7/site-packages/airflow/operators/python.py", line 189, in execute_callable
    return self.python_callable(*self.op_args, **self.op_kwargs)
  File "/opt/airflow/dags/src/cargar_data.py", line 33, in cargar_data
    df = pd.DataFrame(xcom_value)
  File "/home/airflow/.local/lib/python3.7/site-packages/pandas/core/frame.py", line 730, in __init__
    raise ValueError("DataFrame constructor not properly called!")
ValueError: DataFrame constructor not properly called!
[2024-09-15 17:03:12,987] {taskinstance.py:1420} INFO - Marking task as FAILED. dag_id=dag_clima, task_id=cargar_data, execution_date=20240915T170306, start_date=20240915T170311, end_date=20240915T170312
[2024-09-15 17:03:13,005] {standard_task_runner.py:97} ERROR - Failed to execute job 37 for task cargar_data (DataFrame constructor not properly called!; 1327)
[2024-09-15 17:03:13,023] {local_task_job.py:156} INFO - Task exited with return code 1
[2024-09-15 17:03:13,064] {local_task_job.py:273} INFO - 0 downstream tasks scheduled from follow-on schedule check
