[2024-09-15 17:05:10,055] {taskinstance.py:1179} INFO - Dependencies all met for <TaskInstance: dag_clima.cargar_data manual__2024-09-15T17:05:04.973822+00:00 [queued]>
[2024-09-15 17:05:10,066] {taskinstance.py:1179} INFO - Dependencies all met for <TaskInstance: dag_clima.cargar_data manual__2024-09-15T17:05:04.973822+00:00 [queued]>
[2024-09-15 17:05:10,068] {taskinstance.py:1376} INFO - 
--------------------------------------------------------------------------------
[2024-09-15 17:05:10,069] {taskinstance.py:1377} INFO - Starting attempt 1 of 1
[2024-09-15 17:05:10,071] {taskinstance.py:1378} INFO - 
--------------------------------------------------------------------------------
[2024-09-15 17:05:10,088] {taskinstance.py:1397} INFO - Executing <Task(PythonOperator): cargar_data> on 2024-09-15 17:05:04.973822+00:00
[2024-09-15 17:05:10,094] {standard_task_runner.py:52} INFO - Started process 1402 to run task
[2024-09-15 17:05:10,097] {standard_task_runner.py:79} INFO - Running: ['***', 'tasks', 'run', 'dag_clima', 'cargar_data', 'manual__2024-09-15T17:05:04.973822+00:00', '--job-id', '40', '--raw', '--subdir', 'DAGS_FOLDER/dag_clima.py', '--cfg-path', '/tmp/tmpg1u86q66', '--error-file', '/tmp/tmp2onydvvl']
[2024-09-15 17:05:10,098] {standard_task_runner.py:80} INFO - Job 40: Subtask cargar_data
[2024-09-15 17:05:10,179] {task_command.py:371} INFO - Running <TaskInstance: dag_clima.cargar_data manual__2024-09-15T17:05:04.973822+00:00 [running]> on host 4abe27884306
[2024-09-15 17:05:10,259] {taskinstance.py:1591} INFO - Exporting the following env vars:
AIRFLOW_CTX_DAG_OWNER=EmanuelGomez
AIRFLOW_CTX_DAG_ID=dag_clima
AIRFLOW_CTX_TASK_ID=cargar_data
AIRFLOW_CTX_EXECUTION_DATE=2024-09-15T17:05:04.973822+00:00
AIRFLOW_CTX_TRY_NUMBER=1
AIRFLOW_CTX_DAG_RUN_ID=manual__2024-09-15T17:05:04.973822+00:00
[2024-09-15 17:05:11,776] {logging_mixin.py:115} INFO - Conexi√≥n exitosa a Redshift
[2024-09-15 17:05:11,797] {logging_mixin.py:115} INFO - <class 'str'>
[2024-09-15 17:05:11,814] {logging_mixin.py:115} INFO -          time  temperature_max  ...    sede1      sede2
0  2024-09-15            17.82  ...   Devoto   Floresta
1  2024-09-16            21.33  ...   Devoto   Floresta
2  2024-09-17            21.29  ...   Devoto   Floresta
3  2024-09-18            22.26  ...   Devoto   Floresta
4  2024-09-19            21.72  ...  Almagro  Caballito
5  2024-09-20            20.27  ...   Devoto   Floresta
6  2024-09-21            21.46  ...   Devoto   Floresta

[7 rows x 6 columns]
[2024-09-15 17:05:12,172] {taskinstance.py:1909} ERROR - Task failed with exception
Traceback (most recent call last):
  File "/home/airflow/.local/lib/python3.7/site-packages/airflow/operators/python.py", line 171, in execute
    return_value = self.execute_callable()
  File "/home/airflow/.local/lib/python3.7/site-packages/airflow/operators/python.py", line 189, in execute_callable
    return self.python_callable(*self.op_args, **self.op_kwargs)
  File "/opt/airflow/dags/src/cargar_data.py", line 42, in cargar_data
    execute_values(cur, insert_sql, values)
  File "/home/airflow/.local/lib/python3.7/site-packages/psycopg2/extras.py", line 1270, in execute_values
    cur.execute(b''.join(parts))
psycopg2.errors.UndefinedTable: relation "emanuelrgomez19_coderhouse.clima_sede" does not exist

[2024-09-15 17:05:12,190] {taskinstance.py:1420} INFO - Marking task as FAILED. dag_id=dag_clima, task_id=cargar_data, execution_date=20240915T170504, start_date=20240915T170510, end_date=20240915T170512
[2024-09-15 17:05:12,203] {standard_task_runner.py:97} ERROR - Failed to execute job 40 for task cargar_data (relation "emanuelrgomez19_coderhouse.clima_sede" does not exist
; 1402)
[2024-09-15 17:05:12,247] {local_task_job.py:156} INFO - Task exited with return code 1
[2024-09-15 17:05:12,286] {local_task_job.py:273} INFO - 0 downstream tasks scheduled from follow-on schedule check
