[2024-09-15 16:35:21,183] {taskinstance.py:1179} INFO - Dependencies all met for <TaskInstance: dag_clima.transformar_data manual__2024-09-15T16:35:17.613733+00:00 [queued]>
[2024-09-15 16:35:21,195] {taskinstance.py:1179} INFO - Dependencies all met for <TaskInstance: dag_clima.transformar_data manual__2024-09-15T16:35:17.613733+00:00 [queued]>
[2024-09-15 16:35:21,196] {taskinstance.py:1376} INFO - 
--------------------------------------------------------------------------------
[2024-09-15 16:35:21,196] {taskinstance.py:1377} INFO - Starting attempt 1 of 2
[2024-09-15 16:35:21,196] {taskinstance.py:1378} INFO - 
--------------------------------------------------------------------------------
[2024-09-15 16:35:21,213] {taskinstance.py:1397} INFO - Executing <Task(PythonOperator): transformar_data> on 2024-09-15 16:35:17.613733+00:00
[2024-09-15 16:35:21,220] {standard_task_runner.py:52} INFO - Started process 280 to run task
[2024-09-15 16:35:21,225] {standard_task_runner.py:79} INFO - Running: ['***', 'tasks', 'run', 'dag_clima', 'transformar_data', 'manual__2024-09-15T16:35:17.613733+00:00', '--job-id', '4', '--raw', '--subdir', 'DAGS_FOLDER/dag_clima.py', '--cfg-path', '/tmp/tmpsm86_hgh', '--error-file', '/tmp/tmp45bfg790']
[2024-09-15 16:35:21,227] {standard_task_runner.py:80} INFO - Job 4: Subtask transformar_data
[2024-09-15 16:35:21,303] {task_command.py:371} INFO - Running <TaskInstance: dag_clima.transformar_data manual__2024-09-15T16:35:17.613733+00:00 [running]> on host 4abe27884306
[2024-09-15 16:35:21,378] {taskinstance.py:1591} INFO - Exporting the following env vars:
AIRFLOW_CTX_DAG_OWNER=EmanuelGomez
AIRFLOW_CTX_DAG_ID=dag_clima
AIRFLOW_CTX_TASK_ID=transformar_data
AIRFLOW_CTX_EXECUTION_DATE=2024-09-15T16:35:17.613733+00:00
AIRFLOW_CTX_TRY_NUMBER=1
AIRFLOW_CTX_DAG_RUN_ID=manual__2024-09-15T16:35:17.613733+00:00
[2024-09-15 16:35:21,379] {taskinstance.py:1909} ERROR - Task failed with exception
Traceback (most recent call last):
  File "/home/airflow/.local/lib/python3.7/site-packages/airflow/operators/python.py", line 171, in execute
    return_value = self.execute_callable()
  File "/home/airflow/.local/lib/python3.7/site-packages/airflow/operators/python.py", line 189, in execute_callable
    return self.python_callable(*self.op_args, **self.op_kwargs)
  File "/opt/airflow/dags/src/transformar_data.py", line 25, in transformar_data
    df_clima = df_clima[["time","temperature_max","temperature_min","precipitation"]]
UnboundLocalError: local variable 'df_clima' referenced before assignment
[2024-09-15 16:35:21,390] {taskinstance.py:1420} INFO - Marking task as UP_FOR_RETRY. dag_id=dag_clima, task_id=transformar_data, execution_date=20240915T163517, start_date=20240915T163521, end_date=20240915T163521
[2024-09-15 16:35:21,403] {standard_task_runner.py:97} ERROR - Failed to execute job 4 for task transformar_data (local variable 'df_clima' referenced before assignment; 280)
[2024-09-15 16:35:21,437] {local_task_job.py:156} INFO - Task exited with return code 1
[2024-09-15 16:35:21,501] {local_task_job.py:273} INFO - 0 downstream tasks scheduled from follow-on schedule check
