[2024-09-15 16:44:37,148] {taskinstance.py:1179} INFO - Dependencies all met for <TaskInstance: dag_clima.cargar_data manual__2024-09-15T16:39:29.638176+00:00 [queued]>
[2024-09-15 16:44:37,158] {taskinstance.py:1179} INFO - Dependencies all met for <TaskInstance: dag_clima.cargar_data manual__2024-09-15T16:39:29.638176+00:00 [queued]>
[2024-09-15 16:44:37,159] {taskinstance.py:1376} INFO - 
--------------------------------------------------------------------------------
[2024-09-15 16:44:37,160] {taskinstance.py:1377} INFO - Starting attempt 2 of 2
[2024-09-15 16:44:37,161] {taskinstance.py:1378} INFO - 
--------------------------------------------------------------------------------
[2024-09-15 16:44:37,177] {taskinstance.py:1397} INFO - Executing <Task(PythonOperator): cargar_data> on 2024-09-15 16:39:29.638176+00:00
[2024-09-15 16:44:37,182] {standard_task_runner.py:52} INFO - Started process 626 to run task
[2024-09-15 16:44:37,186] {standard_task_runner.py:79} INFO - Running: ['***', 'tasks', 'run', 'dag_clima', 'cargar_data', 'manual__2024-09-15T16:39:29.638176+00:00', '--job-id', '16', '--raw', '--subdir', 'DAGS_FOLDER/dag_clima.py', '--cfg-path', '/tmp/tmpblymv044', '--error-file', '/tmp/tmpra43_sto']
[2024-09-15 16:44:37,188] {standard_task_runner.py:80} INFO - Job 16: Subtask cargar_data
[2024-09-15 16:44:37,262] {task_command.py:371} INFO - Running <TaskInstance: dag_clima.cargar_data manual__2024-09-15T16:39:29.638176+00:00 [running]> on host 4abe27884306
[2024-09-15 16:44:37,335] {taskinstance.py:1591} INFO - Exporting the following env vars:
AIRFLOW_CTX_DAG_OWNER=EmanuelGomez
AIRFLOW_CTX_DAG_ID=dag_clima
AIRFLOW_CTX_TASK_ID=cargar_data
AIRFLOW_CTX_EXECUTION_DATE=2024-09-15T16:39:29.638176+00:00
AIRFLOW_CTX_TRY_NUMBER=2
AIRFLOW_CTX_DAG_RUN_ID=manual__2024-09-15T16:39:29.638176+00:00
[2024-09-15 16:44:39,016] {logging_mixin.py:115} INFO - Conexi√≥n exitosa a Redshift
[2024-09-15 16:44:39,028] {taskinstance.py:1909} ERROR - Task failed with exception
Traceback (most recent call last):
  File "/home/airflow/.local/lib/python3.7/site-packages/airflow/operators/python.py", line 171, in execute
    return_value = self.execute_callable()
  File "/home/airflow/.local/lib/python3.7/site-packages/airflow/operators/python.py", line 189, in execute_callable
    return self.python_callable(*self.op_args, **self.op_kwargs)
  File "/opt/airflow/dags/src/cargar_data.py", line 33, in cargar_data
    df = pd.DataFrame(xcom_value)
  File "/home/airflow/.local/lib/python3.7/site-packages/pandas/core/frame.py", line 730, in __init__
    raise ValueError("DataFrame constructor not properly called!")
ValueError: DataFrame constructor not properly called!
[2024-09-15 16:44:39,045] {taskinstance.py:1420} INFO - Marking task as FAILED. dag_id=dag_clima, task_id=cargar_data, execution_date=20240915T163929, start_date=20240915T164437, end_date=20240915T164439
[2024-09-15 16:44:39,062] {standard_task_runner.py:97} ERROR - Failed to execute job 16 for task cargar_data (DataFrame constructor not properly called!; 626)
[2024-09-15 16:44:39,089] {local_task_job.py:156} INFO - Task exited with return code 1
[2024-09-15 16:44:39,123] {local_task_job.py:273} INFO - 0 downstream tasks scheduled from follow-on schedule check
