[2024-09-15 17:07:52,907] {taskinstance.py:1179} INFO - Dependencies all met for <TaskInstance: dag_clima.cargar_data manual__2024-09-15T17:07:48.616642+00:00 [queued]>
[2024-09-15 17:07:52,917] {taskinstance.py:1179} INFO - Dependencies all met for <TaskInstance: dag_clima.cargar_data manual__2024-09-15T17:07:48.616642+00:00 [queued]>
[2024-09-15 17:07:52,917] {taskinstance.py:1376} INFO - 
--------------------------------------------------------------------------------
[2024-09-15 17:07:52,918] {taskinstance.py:1377} INFO - Starting attempt 1 of 1
[2024-09-15 17:07:52,919] {taskinstance.py:1378} INFO - 
--------------------------------------------------------------------------------
[2024-09-15 17:07:52,933] {taskinstance.py:1397} INFO - Executing <Task(PythonOperator): cargar_data> on 2024-09-15 17:07:48.616642+00:00
[2024-09-15 17:07:52,938] {standard_task_runner.py:52} INFO - Started process 1501 to run task
[2024-09-15 17:07:52,941] {standard_task_runner.py:79} INFO - Running: ['***', 'tasks', 'run', 'dag_clima', 'cargar_data', 'manual__2024-09-15T17:07:48.616642+00:00', '--job-id', '43', '--raw', '--subdir', 'DAGS_FOLDER/dag_clima.py', '--cfg-path', '/tmp/tmpdspsh5ct', '--error-file', '/tmp/tmpm083urwl']
[2024-09-15 17:07:52,942] {standard_task_runner.py:80} INFO - Job 43: Subtask cargar_data
[2024-09-15 17:07:53,014] {task_command.py:371} INFO - Running <TaskInstance: dag_clima.cargar_data manual__2024-09-15T17:07:48.616642+00:00 [running]> on host 4abe27884306
[2024-09-15 17:07:53,089] {taskinstance.py:1591} INFO - Exporting the following env vars:
AIRFLOW_CTX_DAG_OWNER=EmanuelGomez
AIRFLOW_CTX_DAG_ID=dag_clima
AIRFLOW_CTX_TASK_ID=cargar_data
AIRFLOW_CTX_EXECUTION_DATE=2024-09-15T17:07:48.616642+00:00
AIRFLOW_CTX_TRY_NUMBER=1
AIRFLOW_CTX_DAG_RUN_ID=manual__2024-09-15T17:07:48.616642+00:00
[2024-09-15 17:07:54,678] {logging_mixin.py:115} INFO - Conexi√≥n exitosa a Redshift
[2024-09-15 17:07:55,038] {taskinstance.py:1909} ERROR - Task failed with exception
Traceback (most recent call last):
  File "/home/airflow/.local/lib/python3.7/site-packages/airflow/operators/python.py", line 171, in execute
    return_value = self.execute_callable()
  File "/home/airflow/.local/lib/python3.7/site-packages/airflow/operators/python.py", line 189, in execute_callable
    return self.python_callable(*self.op_args, **self.op_kwargs)
  File "/opt/airflow/dags/src/cargar_data.py", line 29, in cargar_data
    create_table_if_not_exists()
  File "/opt/airflow/dags/src/cargar_data.py", line 22, in create_table_if_not_exists
    cur.execute(create_table_query)
psycopg2.errors.InvalidSchemaName: schema "none" does not exist

[2024-09-15 17:07:55,064] {taskinstance.py:1420} INFO - Marking task as FAILED. dag_id=dag_clima, task_id=cargar_data, execution_date=20240915T170748, start_date=20240915T170752, end_date=20240915T170755
[2024-09-15 17:07:55,080] {standard_task_runner.py:97} ERROR - Failed to execute job 43 for task cargar_data (schema "none" does not exist
; 1501)
[2024-09-15 17:07:55,090] {local_task_job.py:156} INFO - Task exited with return code 1
[2024-09-15 17:07:55,134] {local_task_job.py:273} INFO - 0 downstream tasks scheduled from follow-on schedule check
